{
  "openai/gpt-4o-2024-11-20": [
    {
      "task_id": 56,
      "prompt": "### Prompt\nWrite a python function to check if a given number is one less than twice its reverse.\n\n### Signature\ndef rev(num):\n\n### Test\nassert candidate(70) == False",
      "llm_name": "openai/gpt-4o-2024-11-20",
      "error": "Traceback (most recent call last):\n  File \"/Users/madnanrizqu/Code/Research/learn/thesis/languages/python/llm_output_test.py\", line 8, in <module>\n    check(check)\n  File \"/Users/madnanrizqu/Code/Research/learn/thesis/languages/python/llm_output_test.py\", line 4, in check\n    assert candidate(70) == False\n           ^^^^^^^^^^^^^\n  File \"/Users/madnanrizqu/Code/Research/learn/thesis/languages/python/llm_output_test.py\", line 4, in check\n    assert candidate(70) == False\n           ^^^^^^^^^^^^^\nTypeError: 'int' object is not callable\n",
      "solution": "def check(num):\n    # Reverse the number\n    reversed_num = int(str(num)[::-1])\n    # Check if the number is one less than twice its reverse\n    return num == 2 * reversed_num - 1",
      "test_content": "from llm_output import check\n\ndef check(candidate):\n    assert candidate(70) == False\n    assert candidate(23) == False\n    assert candidate(73) == True\n\ncheck(check)",
      "context": "{\"function_name\": \"check\"}",
      "attempt_num": 1
    },
    {
      "task_id": 56,
      "prompt": "### Prompt\nWrite a python function to check if a given number is one less than twice its reverse.\n\n### Signature\ndef rev(num):\n\n### Test\nassert candidate(70) == False\n### Remediation Message\nThis code is not correct as it led to the following issues:\nTraceback (most recent call last):\n  File \"/Users/madnanrizqu/Code/Research/learn/thesis/languages/python/llm_output_test.py\", line 8, in <module>\n    check(check)\n  File \"/Users/madnanrizqu/Code/Research/learn/thesis/languages/python/llm_output_test.py\", line 4, in check\n    assert candidate(70) == False\n           ^^^^^^^^^^^^^\n  File \"/Users/madnanrizqu/Code/Research/learn/thesis/languages/python/llm_output_test.py\", line 4, in check\n    assert candidate(70) == False\n           ^^^^^^^^^^^^^\nTypeError: 'int' object is not callable\n",
      "llm_name": "openai/gpt-4o-2024-11-20",
      "error": "Traceback (most recent call last):\n  File \"/Users/madnanrizqu/Code/Research/learn/thesis/languages/python/llm_output_test.py\", line 8, in <module>\n    check(check)\n  File \"/Users/madnanrizqu/Code/Research/learn/thesis/languages/python/llm_output_test.py\", line 4, in check\n    assert candidate(70) == False\n           ^^^^^^^^^^^^^\n  File \"/Users/madnanrizqu/Code/Research/learn/thesis/languages/python/llm_output_test.py\", line 4, in check\n    assert candidate(70) == False\n           ^^^^^^^^^^^^^\nTypeError: 'int' object is not callable\n",
      "solution": "def check(num: int) -> bool:\n    # Reverse the number\n    reversed_num = int(str(num)[::-1])\n    # Check if the number is one less than twice its reverse\n    return num == 2 * reversed_num - 1",
      "test_content": "from llm_output import check\n\ndef check(candidate):\n    assert candidate(70) == False\n    assert candidate(23) == False\n    assert candidate(73) == True\n\ncheck(check)",
      "context": "{\"function_name\": \"check\"}",
      "attempt_num": 2
    },
    {
      "task_id": 56,
      "prompt": "### Prompt\nWrite a python function to check if a given number is one less than twice its reverse.\n\n### Signature\ndef rev(num):\n\n### Test\nassert candidate(70) == False\n### Remediation Message\nThis code is not correct as it led to the following issues:\nTraceback (most recent call last):\n  File \"/Users/madnanrizqu/Code/Research/learn/thesis/languages/python/llm_output_test.py\", line 8, in <module>\n    check(check)\n  File \"/Users/madnanrizqu/Code/Research/learn/thesis/languages/python/llm_output_test.py\", line 4, in check\n    assert candidate(70) == False\n           ^^^^^^^^^^^^^\n  File \"/Users/madnanrizqu/Code/Research/learn/thesis/languages/python/llm_output_test.py\", line 4, in check\n    assert candidate(70) == False\n           ^^^^^^^^^^^^^\nTypeError: 'int' object is not callable\n",
      "llm_name": "openai/gpt-4o-2024-11-20",
      "error": "Traceback (most recent call last):\n  File \"/Users/madnanrizqu/Code/Research/learn/thesis/languages/python/llm_output_test.py\", line 8, in <module>\n    check(check)\n  File \"/Users/madnanrizqu/Code/Research/learn/thesis/languages/python/llm_output_test.py\", line 4, in check\n    assert candidate(70) == False\n           ^^^^^^^^^^^^^\n  File \"/Users/madnanrizqu/Code/Research/learn/thesis/languages/python/llm_output_test.py\", line 4, in check\n    assert candidate(70) == False\n           ^^^^^^^^^^^^^\nTypeError: 'int' object is not callable\n",
      "solution": "def check(num: int) -> bool:\n    # Reverse the number\n    reversed_num = int(str(num)[::-1])\n    # Check if the number is one less than twice its reverse\n    return num == 2 * reversed_num - 1",
      "test_content": "from llm_output import check\n\ndef check(candidate):\n    assert candidate(70) == False\n    assert candidate(23) == False\n    assert candidate(73) == True\n\ncheck(check)",
      "context": "{\"function_name\": \"check\"}",
      "attempt_num": 3
    }
  ]
}